#VRML_SIM R2019a utf8
WorldInfo {
}
Viewpoint {
  orientation 0.01696937062431656 -0.9953475518859392 0.09484351013792279 2.7891134198015197
  position -1.0006439775446938 3.6460157105381414 -2.315123290461219
}
TexturedBackground {
}
TexturedBackgroundLight {
}
Floor {
}
Solid {
  translation 0 0.2 0
  rotation 0 0 1 6.283185307179586
  children [
    DEF Base Transform {
      translation 0 1 0
      children [
        Transform {
          translation 0 2.019999999999999 0
          children [
            Shape {
              appearance Appearance {
                material Material {
                  diffuseColor 0 0 1
                }
              }
              geometry Box {
                size 0.1 1.5 0.1
              }
            }
          ]
        }
        HingeJoint {
          jointParameters HingeJointParameters {
            position -19.78103701447851
            axis 0 0 1
            anchor -0.09999999999999999 2.7 0
          }
          endPoint Solid {
            translation -0.09999999999999999 2.7 0
            children [
              Shape {
                appearance Appearance {
                  material Material {
                    diffuseColor 0 1 0
                  }
                }
                geometry Box {
                  size 0.1 0.2 0.005
                }
              }
            ]
            name "Helix(1)"
            physics Physics {
            }
          }
        }
        Transform {
          translation 0 0 -1
          rotation 0 0 -1 4.712389004359173
          children [
            DEF Barra Shape {
              appearance Appearance {
                material Material {
                  diffuseColor 0 0 1
                }
              }
              geometry Cylinder {
                radius 0.035
              }
            }
          ]
        }
        Transform {
          translation 0 0 1
          rotation 0 0 -1 4.712389004359173
          children [
            USE Barra
          ]
        }
        Transform {
          translation 1 0 0
          rotation -1 0 0 4.712389004359173
          children [
            USE Barra
          ]
        }
        Transform {
          translation -1 0 0
          rotation -1 0 0 4.712389004359173
          children [
            USE Barra
          ]
        }
        Transform {
          translation 1 0 -1
          rotation -0.7071067811865475 0 -0.7071067811865475 5.699130716894473
          children [
            DEF POSTE Shape {
              appearance DEF Color1 Appearance {
                material Material {
                  diffuseColor 0 0 1
                }
              }
              geometry Cylinder {
                height 3
                radius 0.035
              }
            }
          ]
        }
        Transform {
          translation -1 0 -1
          rotation -0.7071068905932484 0 0.7071066717798298 5.699130716894473
          children [
            USE POSTE
          ]
        }
        Transform {
          translation -1 0 1
          rotation 0.7071067811865476 0 0.7071067811865476 5.699130716894473
          children [
            USE POSTE
          ]
        }
        Transform {
          translation 1 0 1
          rotation 0.7071068905932484 0 -0.7071066717798297 5.699130716894473
          children [
            USE POSTE
          ]
        }
      ]
    }
    DEF Helicebase Transform {
      translation 0.09000000000000007 3.4899999999999842 0
      children [
        Transform {
          translation -0.005 0.2 0
          rotation 0 0 1 1.5707963220000003
          children [
            Shape {
              appearance Appearance {
                material Material {
                  diffuseColor 0 1 0
                }
              }
              geometry Cylinder {
                height 0.1
                radius 0.05
              }
            }
          ]
        }
        HingeJoint {
          jointParameters HingeJointParameters {
            position -19.78103701447851
            anchor 0.05 0.2 0
          }
          endPoint Solid {
            translation 0.05 0.19999215977030949 4.087145861765337e-11
            rotation 1 5.0859067191280154e-14 1.4903366608012502e-13 2.115181419326384
            children [
              DEF Helix Group {
                children [
                  Transform {
                    translation 0 -0.17 0
                    children [
                      DEF panel Shape {
                        appearance DEF Color2 Appearance {
                          material Material {
                            diffuseColor 1 0 0
                          }
                        }
                        geometry Box {
                          size 0.01 0.1 0.05
                        }
                      }
                    ]
                  }
                  Transform {
                    translation 0 0.17 0
                    children [
                      USE panel
                    ]
                  }
                  Transform {
                    translation 0 0.12020815308990583 0.12020815251352027
                    rotation 1 0 0 0.7853981610000004
                    children [
                      USE panel
                    ]
                  }
                  Transform {
                    translation 0 -0.120208 -0.120208
                    rotation 1 0 0 0.7853981610000004
                    children [
                      USE panel
                    ]
                  }
                  Transform {
                    translation 0 0.12020815193713462 -0.12020815366629152
                    rotation 0.9999999999999999 0 0 2.3561944830000003
                    children [
                      USE panel
                    ]
                  }
                  Transform {
                    translation 0 -0.120208 0.120208
                    rotation 0.9999999999999999 0 0 2.3561944830000003
                    children [
                      USE panel
                    ]
                  }
                  Transform {
                    translation 0 -4.075662203142233e-09 -0.16999999999999998
                    rotation -1 0 0 4.712389004359173
                    children [
                      USE panel
                    ]
                  }
                  Transform {
                    translation 0 4.07566e-09 0.17
                    rotation -1 0 0 4.712389004359173
                    children [
                      USE panel
                    ]
                  }
                  Transform {
                    children [
                      DEF Molino Shape {
                        appearance USE Color2
                        geometry Box {
                          size 0.01 0.25 0.01
                        }
                      }
                    ]
                  }
                  Transform {
                    rotation 1 0 0 1.5707963220000003
                    children [
                      USE Molino
                    ]
                  }
                  Transform {
                    rotation 1 0 0 2.3561944830000003
                    children [
                      USE Molino
                    ]
                  }
                  Transform {
                    rotation -1 0 0 5.497787165359173
                    children [
                      USE Molino
                    ]
                  }
                ]
              }
            ]
            name "Helix"
            boundingObject USE Helix
            physics Physics {
            }
          }
        }
      ]
    }
  ]
}
